{
    DataVersion: 3955,
    size: [3, 6, 3],
    data: [
        {pos: [0, 0, 0], state: "anvilcraft:heater{overload:false}", nbt: {id: "anvilcraft:heater"}},
        {pos: [0, 0, 1], state: "anvilcraft:heater{overload:false}", nbt: {id: "anvilcraft:heater"}},
        {pos: [0, 0, 2], state: "anvilcraft:heater{overload:false}", nbt: {id: "anvilcraft:heater"}},
        {pos: [1, 0, 0], state: "anvilcraft:heater{overload:false}", nbt: {id: "anvilcraft:heater"}},
        {pos: [1, 0, 1], state: "anvilcraft:heater{overload:false}", nbt: {id: "anvilcraft:heater"}},
        {pos: [1, 0, 2], state: "anvilcraft:heater{overload:false}", nbt: {id: "anvilcraft:heater"}},
        {pos: [2, 0, 0], state: "anvilcraft:heater{overload:false}", nbt: {id: "anvilcraft:heater"}},
        {pos: [2, 0, 1], state: "anvilcraft:heater{overload:false}", nbt: {id: "anvilcraft:heater"}},
        {pos: [2, 0, 2], state: "anvilcraft:heater{overload:false}", nbt: {id: "anvilcraft:heater"}},
        {pos: [0, 1, 0], state: "create:fluid_tank{bottom:true,shape:plain,top:false}", nbt: {Boiler: {ActiveHeat: 9, Engines: 1, PassiveHeat: 0b, Supply: 0.0f, Update: 0b, Whistles: 0}, Height: 4, LastKnownPos: [I; 18, 57, -37], Luminosity: 0, Owner: [I; 940439953, -167562164, -1601161573, -1389718966], Size: 3, TankContent: {}, Window: 0b, id: "create:fluid_tank"}},
        {pos: [0, 1, 1], state: "create:fluid_tank{bottom:true,shape:plain,top:false}", nbt: {Boiler: {ActiveHeat: 0, Engines: 0, PassiveHeat: 0b, Supply: 0.0f, Update: 0b, Whistles: 0}, Controller: [I; 18, 57, -37], LastKnownPos: [I; 18, 57, -36], Luminosity: 0, Owner: [I; 940439953, -167562164, -1601161573, -1389718966], id: "create:fluid_tank"}},
        {pos: [0, 1, 2], state: "create:fluid_tank{bottom:true,shape:plain,top:false}", nbt: {Boiler: {ActiveHeat: 0, Engines: 0, PassiveHeat: 0b, Supply: 0.0f, Update: 0b, Whistles: 0}, Controller: [I; 18, 57, -37], LastKnownPos: [I; 18, 57, -35], Luminosity: 0, Owner: [I; 940439953, -167562164, -1601161573, -1389718966], id: "create:fluid_tank"}},
        {pos: [1, 1, 0], state: "create:fluid_tank{bottom:true,shape:plain,top:false}", nbt: {Boiler: {ActiveHeat: 0, Engines: 0, PassiveHeat: 0b, Supply: 0.0f, Update: 0b, Whistles: 0}, Controller: [I; 18, 57, -37], LastKnownPos: [I; 19, 57, -37], Luminosity: 0, Owner: [I; 940439953, -167562164, -1601161573, -1389718966], id: "create:fluid_tank"}},
        {pos: [1, 1, 1], state: "create:fluid_tank{bottom:true,shape:plain,top:false}", nbt: {Boiler: {ActiveHeat: 0, Engines: 0, PassiveHeat: 0b, Supply: 0.0f, Update: 1b, Whistles: 0}, Controller: [I; 18, 57, -37], LastKnownPos: [I; 19, 57, -36], Luminosity: 0, Owner: [I; 940439953, -167562164, -1601161573, -1389718966], id: "create:fluid_tank"}},
        {pos: [1, 1, 2], state: "create:fluid_tank{bottom:true,shape:plain,top:false}", nbt: {Boiler: {ActiveHeat: 0, Engines: 0, PassiveHeat: 0b, Supply: 0.0f, Update: 0b, Whistles: 0}, Controller: [I; 18, 57, -37], LastKnownPos: [I; 19, 57, -35], Luminosity: 0, Owner: [I; 940439953, -167562164, -1601161573, -1389718966], id: "create:fluid_tank"}},
        {pos: [2, 1, 0], state: "create:fluid_tank{bottom:true,shape:plain,top:false}", nbt: {Boiler: {ActiveHeat: 0, Engines: 0, PassiveHeat: 0b, Supply: 0.0f, Update: 0b, Whistles: 0}, Controller: [I; 18, 57, -37], LastKnownPos: [I; 20, 57, -37], Luminosity: 0, Owner: [I; 940439953, -167562164, -1601161573, -1389718966], id: "create:fluid_tank"}},
        {pos: [2, 1, 1], state: "create:fluid_tank{bottom:true,shape:plain,top:false}", nbt: {Boiler: {ActiveHeat: 0, Engines: 0, PassiveHeat: 0b, Supply: 0.0f, Update: 0b, Whistles: 0}, Controller: [I; 18, 57, -37], LastKnownPos: [I; 20, 57, -36], Luminosity: 0, Owner: [I; 940439953, -167562164, -1601161573, -1389718966], id: "create:fluid_tank"}},
        {pos: [2, 1, 2], state: "create:fluid_tank{bottom:true,shape:plain,top:false}", nbt: {Boiler: {ActiveHeat: 0, Engines: 0, PassiveHeat: 0b, Supply: 0.0f, Update: 0b, Whistles: 0}, Controller: [I; 18, 57, -37], LastKnownPos: [I; 20, 57, -35], Luminosity: 0, Owner: [I; 940439953, -167562164, -1601161573, -1389718966], id: "create:fluid_tank"}},
        {pos: [0, 2, 0], state: "create:fluid_tank{bottom:false,shape:plain,top:false}", nbt: {Boiler: {ActiveHeat: 0, Engines: 0, PassiveHeat: 0b, Supply: 0.0f, Update: 0b, Whistles: 0}, Controller: [I; 18, 57, -37], LastKnownPos: [I; 18, 58, -37], Luminosity: 0, Owner: [I; 940439953, -167562164, -1601161573, -1389718966], id: "create:fluid_tank"}},
        {pos: [0, 2, 1], state: "create:fluid_tank{bottom:false,shape:plain,top:false}", nbt: {Boiler: {ActiveHeat: 0, Engines: 0, PassiveHeat: 0b, Supply: 0.0f, Update: 0b, Whistles: 0}, Controller: [I; 18, 57, -37], LastKnownPos: [I; 18, 58, -36], Luminosity: 0, Owner: [I; 940439953, -167562164, -1601161573, -1389718966], id: "create:fluid_tank"}},
        {pos: [0, 2, 2], state: "create:fluid_tank{bottom:false,shape:plain,top:false}", nbt: {Boiler: {ActiveHeat: 0, Engines: 0, PassiveHeat: 0b, Supply: 0.0f, Update: 0b, Whistles: 0}, Controller: [I; 18, 57, -37], LastKnownPos: [I; 18, 58, -35], Luminosity: 0, Owner: [I; 940439953, -167562164, -1601161573, -1389718966], id: "create:fluid_tank"}},
        {pos: [1, 2, 0], state: "create:fluid_tank{bottom:false,shape:plain,top:false}", nbt: {Boiler: {ActiveHeat: 0, Engines: 0, PassiveHeat: 0b, Supply: 0.0f, Update: 0b, Whistles: 0}, Controller: [I; 18, 57, -37], LastKnownPos: [I; 19, 58, -37], Luminosity: 0, Owner: [I; 940439953, -167562164, -1601161573, -1389718966], id: "create:fluid_tank"}},
        {pos: [1, 2, 1], state: "create:fluid_tank{bottom:false,shape:plain,top:false}", nbt: {Boiler: {ActiveHeat: 0, Engines: 0, PassiveHeat: 0b, Supply: 0.0f, Update: 0b, Whistles: 0}, Controller: [I; 18, 57, -37], LastKnownPos: [I; 19, 58, -36], Luminosity: 0, Owner: [I; 940439953, -167562164, -1601161573, -1389718966], id: "create:fluid_tank"}},
        {pos: [1, 2, 2], state: "create:fluid_tank{bottom:false,shape:plain,top:false}", nbt: {Boiler: {ActiveHeat: 0, Engines: 0, PassiveHeat: 0b, Supply: 0.0f, Update: 0b, Whistles: 0}, Controller: [I; 18, 57, -37], LastKnownPos: [I; 19, 58, -35], Luminosity: 0, Owner: [I; 940439953, -167562164, -1601161573, -1389718966], id: "create:fluid_tank"}},
        {pos: [2, 2, 0], state: "create:fluid_tank{bottom:false,shape:plain,top:false}", nbt: {Boiler: {ActiveHeat: 0, Engines: 0, PassiveHeat: 0b, Supply: 0.0f, Update: 0b, Whistles: 0}, Controller: [I; 18, 57, -37], LastKnownPos: [I; 20, 58, -37], Luminosity: 0, Owner: [I; 940439953, -167562164, -1601161573, -1389718966], id: "create:fluid_tank"}},
        {pos: [2, 2, 1], state: "create:fluid_tank{bottom:false,shape:plain,top:false}", nbt: {Boiler: {ActiveHeat: 0, Engines: 0, PassiveHeat: 0b, Supply: 0.0f, Update: 0b, Whistles: 0}, Controller: [I; 18, 57, -37], LastKnownPos: [I; 20, 58, -36], Luminosity: 0, Owner: [I; 940439953, -167562164, -1601161573, -1389718966], id: "create:fluid_tank"}},
        {pos: [2, 2, 2], state: "create:fluid_tank{bottom:false,shape:plain,top:false}", nbt: {Boiler: {ActiveHeat: 0, Engines: 0, PassiveHeat: 0b, Supply: 0.0f, Update: 0b, Whistles: 0}, Controller: [I; 18, 57, -37], LastKnownPos: [I; 20, 58, -35], Luminosity: 0, Owner: [I; 940439953, -167562164, -1601161573, -1389718966], id: "create:fluid_tank"}},
        {pos: [0, 3, 0], state: "create:fluid_tank{bottom:false,shape:plain,top:false}", nbt: {Boiler: {ActiveHeat: 0, Engines: 0, PassiveHeat: 0b, Supply: 0.0f, Update: 0b, Whistles: 0}, Controller: [I; 18, 57, -37], LastKnownPos: [I; 18, 59, -37], Luminosity: 0, Owner: [I; 940439953, -167562164, -1601161573, -1389718966], id: "create:fluid_tank"}},
        {pos: [0, 3, 1], state: "create:fluid_tank{bottom:false,shape:plain,top:false}", nbt: {Boiler: {ActiveHeat: 0, Engines: 0, PassiveHeat: 0b, Supply: 0.0f, Update: 0b, Whistles: 0}, Controller: [I; 18, 57, -37], LastKnownPos: [I; 18, 59, -36], Luminosity: 0, Owner: [I; 940439953, -167562164, -1601161573, -1389718966], id: "create:fluid_tank"}},
        {pos: [0, 3, 2], state: "create:fluid_tank{bottom:false,shape:plain,top:false}", nbt: {Boiler: {ActiveHeat: 0, Engines: 0, PassiveHeat: 0b, Supply: 0.0f, Update: 0b, Whistles: 0}, Controller: [I; 18, 57, -37], LastKnownPos: [I; 18, 59, -35], Luminosity: 0, Owner: [I; 940439953, -167562164, -1601161573, -1389718966], id: "create:fluid_tank"}},
        {pos: [1, 3, 0], state: "create:fluid_tank{bottom:false,shape:plain,top:false}", nbt: {Boiler: {ActiveHeat: 0, Engines: 0, PassiveHeat: 0b, Supply: 0.0f, Update: 0b, Whistles: 0}, Controller: [I; 18, 57, -37], LastKnownPos: [I; 19, 59, -37], Luminosity: 0, Owner: [I; 940439953, -167562164, -1601161573, -1389718966], id: "create:fluid_tank"}},
        {pos: [1, 3, 1], state: "create:fluid_tank{bottom:false,shape:plain,top:false}", nbt: {Boiler: {ActiveHeat: 0, Engines: 0, PassiveHeat: 0b, Supply: 0.0f, Update: 0b, Whistles: 0}, Controller: [I; 18, 57, -37], LastKnownPos: [I; 19, 59, -36], Luminosity: 0, Owner: [I; 940439953, -167562164, -1601161573, -1389718966], id: "create:fluid_tank"}},
        {pos: [1, 3, 2], state: "create:fluid_tank{bottom:false,shape:plain,top:false}", nbt: {Boiler: {ActiveHeat: 0, Engines: 0, PassiveHeat: 0b, Supply: 0.0f, Update: 0b, Whistles: 0}, Controller: [I; 18, 57, -37], LastKnownPos: [I; 19, 59, -35], Luminosity: 0, Owner: [I; 940439953, -167562164, -1601161573, -1389718966], id: "create:fluid_tank"}},
        {pos: [2, 3, 0], state: "create:fluid_tank{bottom:false,shape:plain,top:false}", nbt: {Boiler: {ActiveHeat: 0, Engines: 0, PassiveHeat: 0b, Supply: 0.0f, Update: 0b, Whistles: 0}, Controller: [I; 18, 57, -37], LastKnownPos: [I; 20, 59, -37], Luminosity: 0, Owner: [I; 940439953, -167562164, -1601161573, -1389718966], id: "create:fluid_tank"}},
        {pos: [2, 3, 1], state: "create:fluid_tank{bottom:false,shape:plain,top:false}", nbt: {Boiler: {ActiveHeat: 0, Engines: 0, PassiveHeat: 0b, Supply: 0.0f, Update: 0b, Whistles: 0}, Controller: [I; 18, 57, -37], LastKnownPos: [I; 20, 59, -36], Luminosity: 0, Owner: [I; 940439953, -167562164, -1601161573, -1389718966], id: "create:fluid_tank"}},
        {pos: [2, 3, 2], state: "create:fluid_tank{bottom:false,shape:plain,top:false}", nbt: {Boiler: {ActiveHeat: 0, Engines: 0, PassiveHeat: 0b, Supply: 0.0f, Update: 0b, Whistles: 0}, Controller: [I; 18, 57, -37], LastKnownPos: [I; 20, 59, -35], Luminosity: 0, Owner: [I; 940439953, -167562164, -1601161573, -1389718966], id: "create:fluid_tank"}},
        {pos: [0, 4, 0], state: "create:fluid_tank{bottom:false,shape:plain,top:true}", nbt: {Boiler: {ActiveHeat: 0, Engines: 0, PassiveHeat: 0b, Supply: 0.0f, Update: 0b, Whistles: 0}, Controller: [I; 18, 57, -37], LastKnownPos: [I; 18, 60, -37], Luminosity: 0, Owner: [I; 940439953, -167562164, -1601161573, -1389718966], id: "create:fluid_tank"}},
        {pos: [0, 4, 1], state: "create:fluid_tank{bottom:false,shape:plain,top:true}", nbt: {Boiler: {ActiveHeat: 0, Engines: 0, PassiveHeat: 0b, Supply: 0.0f, Update: 0b, Whistles: 0}, Controller: [I; 18, 57, -37], LastKnownPos: [I; 18, 60, -36], Luminosity: 0, Owner: [I; 940439953, -167562164, -1601161573, -1389718966], id: "create:fluid_tank"}},
        {pos: [0, 4, 2], state: "create:fluid_tank{bottom:false,shape:plain,top:true}", nbt: {Boiler: {ActiveHeat: 0, Engines: 0, PassiveHeat: 0b, Supply: 0.0f, Update: 0b, Whistles: 0}, Controller: [I; 18, 57, -37], LastKnownPos: [I; 18, 60, -35], Luminosity: 0, Owner: [I; 940439953, -167562164, -1601161573, -1389718966], id: "create:fluid_tank"}},
        {pos: [1, 4, 0], state: "create:fluid_tank{bottom:false,shape:plain,top:true}", nbt: {Boiler: {ActiveHeat: 0, Engines: 0, PassiveHeat: 0b, Supply: 0.0f, Update: 0b, Whistles: 0}, Controller: [I; 18, 57, -37], LastKnownPos: [I; 19, 60, -37], Luminosity: 0, Owner: [I; 940439953, -167562164, -1601161573, -1389718966], id: "create:fluid_tank"}},
        {pos: [1, 4, 1], state: "create:fluid_tank{bottom:false,shape:plain,top:true}", nbt: {Boiler: {ActiveHeat: 0, Engines: 0, PassiveHeat: 0b, Supply: 0.0f, Update: 0b, Whistles: 0}, Controller: [I; 18, 57, -37], LastKnownPos: [I; 19, 60, -36], Luminosity: 0, Owner: [I; 940439953, -167562164, -1601161573, -1389718966], id: "create:fluid_tank"}},
        {pos: [1, 4, 2], state: "create:fluid_tank{bottom:false,shape:plain,top:true}", nbt: {Boiler: {ActiveHeat: 0, Engines: 0, PassiveHeat: 0b, Supply: 0.0f, Update: 0b, Whistles: 0}, Controller: [I; 18, 57, -37], LastKnownPos: [I; 19, 60, -35], Luminosity: 0, Owner: [I; 940439953, -167562164, -1601161573, -1389718966], id: "create:fluid_tank"}},
        {pos: [2, 4, 0], state: "create:fluid_tank{bottom:false,shape:plain,top:true}", nbt: {Boiler: {ActiveHeat: 0, Engines: 0, PassiveHeat: 0b, Supply: 0.0f, Update: 0b, Whistles: 0}, Controller: [I; 18, 57, -37], LastKnownPos: [I; 20, 60, -37], Luminosity: 0, Owner: [I; 940439953, -167562164, -1601161573, -1389718966], id: "create:fluid_tank"}},
        {pos: [2, 4, 1], state: "create:fluid_tank{bottom:false,shape:plain,top:true}", nbt: {Boiler: {ActiveHeat: 0, Engines: 0, PassiveHeat: 0b, Supply: 0.0f, Update: 0b, Whistles: 0}, Controller: [I; 18, 57, -37], LastKnownPos: [I; 20, 60, -36], Luminosity: 0, Owner: [I; 940439953, -167562164, -1601161573, -1389718966], id: "create:fluid_tank"}},
        {pos: [2, 4, 2], state: "create:fluid_tank{bottom:false,shape:plain,top:true}", nbt: {Boiler: {ActiveHeat: 0, Engines: 0, PassiveHeat: 0b, Supply: 0.0f, Update: 0b, Whistles: 0}, Controller: [I; 18, 57, -37], LastKnownPos: [I; 20, 60, -35], Luminosity: 0, Owner: [I; 940439953, -167562164, -1601161573, -1389718966], id: "create:fluid_tank"}},
        {pos: [1, 5, 1], state: "create:steam_engine{face:floor,facing:south,waterlogged:false}", nbt: {Owner: [I; 940439953, -167562164, -1601161573, -1389718966], ScrollValue: 0, id: "create:steam_engine"}}
    ],
    entities: [],
    palette: [
        "anvilcraft:heater{overload:false}",
        "create:fluid_tank{bottom:true,shape:plain,top:false}",
        "create:fluid_tank{bottom:false,shape:plain,top:false}",
        "create:fluid_tank{bottom:false,shape:plain,top:true}",
        "create:steam_engine{face:floor,facing:south,waterlogged:false}"
    ]
}